{"uuid": "d9d3c3ca-b810-4a61-b239-a78008b77659", "children": ["20e28f7b-8ca9-497e-9dba-8ff2235ab2c7", "d4f0e2ae-0a18-483f-ae61-43e2f10b8654", "ff3b505a-e0ff-49b7-8e41-4002c0c6b4a8", "19a0c8df-a816-4609-a33e-d845fe8458cf", "0c76f868-c552-49cf-b27e-990a65651ada"], "befores": [{"name": "_xunit_setup_class_fixture_Test_loop", "status": "broken", "statusDetails": {"message": "socket.timeout: timed out\n", "trace": "  File \"C:\\Users\\Administrator\\AppData\\Local\\Programs\\Python\\Python39\\lib\\site-packages\\pluggy\\_callers.py\", line 39, in _multicall\n    res = hook_impl.function(*args)\n  File \"C:\\Users\\Administrator\\AppData\\Local\\Programs\\Python\\Python39\\lib\\site-packages\\_pytest\\fixtures.py\", line 1128, in pytest_fixture_setup\n    result = call_fixture_func(fixturefunc, request, kwargs)\n  File \"C:\\Users\\Administrator\\AppData\\Local\\Programs\\Python\\Python39\\lib\\site-packages\\_pytest\\fixtures.py\", line 900, in call_fixture_func\n    fixture_result = next(generator)\n  File \"C:\\Users\\Administrator\\AppData\\Local\\Programs\\Python\\Python39\\lib\\site-packages\\_pytest\\python.py\", line 864, in xunit_setup_class_fixture\n    _call_with_optional_argument(func, self.obj)\n  File \"C:\\Users\\Administrator\\AppData\\Local\\Programs\\Python\\Python39\\lib\\site-packages\\_pytest\\python.py\", line 786, in _call_with_optional_argument\n    func(arg)\n  File \"c:\\Users\\Administrator\\Desktop\\code\\wanwan1\\test_loop.py\", line 18, in setup_class\n    self.p1.tel_main()\n  File \"c:\\Users\\Administrator\\Desktop\\code\\wanwan1\\login.py\", line 36, in tel_main\n    self.tn = telnetlib.Telnet(self.ip,self.port,timeout=10)\n  File \"C:\\Users\\Administrator\\AppData\\Local\\Programs\\Python\\Python39\\lib\\telnetlib.py\", line 218, in __init__\n    self.open(host, port, timeout)\n  File \"C:\\Users\\Administrator\\AppData\\Local\\Programs\\Python\\Python39\\lib\\telnetlib.py\", line 235, in open\n    self.sock = socket.create_connection((host, port), timeout)\n  File \"C:\\Users\\Administrator\\AppData\\Local\\Programs\\Python\\Python39\\lib\\socket.py\", line 844, in create_connection\n    raise err\n  File \"C:\\Users\\Administrator\\AppData\\Local\\Programs\\Python\\Python39\\lib\\socket.py\", line 832, in create_connection\n    sock.connect(sa)\n"}, "start": 1677463034927, "stop": 1677463044927}], "start": 1677463034927, "stop": 1677463045114}