{"uuid": "c62cdc5f-daad-4298-83b4-d44c6046a90c", "children": ["56d35219-69c4-41cd-a572-5c5a1fd55fb8", "cbbd7f86-73cb-4551-9566-2af608d7ef5e", "df3e7f07-482e-4c2a-bd4d-304a72c35229", "83d70c9d-f4b1-4eb2-8ae7-36794e24d618", "096ea5ea-af27-443d-8152-14eb0e0d1490"], "befores": [{"name": "_xunit_setup_class_fixture_Test_loop", "status": "broken", "statusDetails": {"message": "socket.timeout: timed out\n", "trace": "  File \"C:\\Users\\Administrator\\AppData\\Local\\Programs\\Python\\Python39\\lib\\site-packages\\pluggy\\_callers.py\", line 39, in _multicall\n    res = hook_impl.function(*args)\n  File \"C:\\Users\\Administrator\\AppData\\Local\\Programs\\Python\\Python39\\lib\\site-packages\\_pytest\\fixtures.py\", line 1128, in pytest_fixture_setup\n    result = call_fixture_func(fixturefunc, request, kwargs)\n  File \"C:\\Users\\Administrator\\AppData\\Local\\Programs\\Python\\Python39\\lib\\site-packages\\_pytest\\fixtures.py\", line 900, in call_fixture_func\n    fixture_result = next(generator)\n  File \"C:\\Users\\Administrator\\AppData\\Local\\Programs\\Python\\Python39\\lib\\site-packages\\_pytest\\python.py\", line 864, in xunit_setup_class_fixture\n    _call_with_optional_argument(func, self.obj)\n  File \"C:\\Users\\Administrator\\AppData\\Local\\Programs\\Python\\Python39\\lib\\site-packages\\_pytest\\python.py\", line 786, in _call_with_optional_argument\n    func(arg)\n  File \"c:\\Users\\Administrator\\Desktop\\code\\wanwan1\\test_loop.py\", line 18, in setup_class\n    self.p1.tel_main()\n  File \"c:\\Users\\Administrator\\Desktop\\code\\wanwan1\\login.py\", line 36, in tel_main\n    self.tn = telnetlib.Telnet(self.ip,self.port,timeout=10)\n  File \"C:\\Users\\Administrator\\AppData\\Local\\Programs\\Python\\Python39\\lib\\telnetlib.py\", line 218, in __init__\n    self.open(host, port, timeout)\n  File \"C:\\Users\\Administrator\\AppData\\Local\\Programs\\Python\\Python39\\lib\\telnetlib.py\", line 235, in open\n    self.sock = socket.create_connection((host, port), timeout)\n  File \"C:\\Users\\Administrator\\AppData\\Local\\Programs\\Python\\Python39\\lib\\socket.py\", line 844, in create_connection\n    raise err\n  File \"C:\\Users\\Administrator\\AppData\\Local\\Programs\\Python\\Python39\\lib\\socket.py\", line 832, in create_connection\n    sock.connect(sa)\n"}, "start": 1676260409436, "stop": 1676260419437}], "start": 1676260409436, "stop": 1676260420307}